Workbook

Sheet Resumen Presupuesto
A1: PRESUPUESTO DE PROYECTO - INGENIERÍA DE SOFTWARE
A3: RECURSO HUMANO
A5: Concepto | B5: Costo Unitario (USD) | C5: Costo Total Mensual (USD)
A6: Ingeniero de Software 1 | B6: $2,000.00 | C6: $450.00
A7: Ingeniero de Software 2 | B7: $2,000.00 | C7: $450.00
A8: Ingeniero de Software 3 | B8: $2,000.00 | C8: $450.00
A10: SUBTOTAL RECURSO HUMANO | C10: $1,350.00
A12: RECURSOS MATERIALES - DEPRECIACIÓN
A14: Computadoras | B14: Valor Inicial | C14: Depreciación Mensual
A15: PC 1 | B15: $1,000.00 | C15: $9.26
A16: PC 2 | B16: $1,200.00 | C16: $11.11
A17: PC 3 | B17: $1,200.00 | C17: $11.11
A18: SUBTOTAL DEPREC. COMPUTADORAS | C18: $31.48
A20: Celulares | B20: Valor Inicial | C20: Depreciación Mensual
A21: Celular 1 | B21: $130.00 | C21: $1.20
A22: Celular 2 | B22: $150.00 | C22: $1.39
A23: Celular 3 | B23: $150.00 | C23: $1.39
A24: SUBTOTAL DEPREC. CELULARES | C24: $3.98
A26: SERVICIOS E INFRAESTRUCTURA
A28: Internet | C28: $30.00
A29: Luz | C29: $50.00
A30: Agua | C30: $20.00
A31: Transporte | C31: $80.00
A32: SUBTOTAL SERVICIOS | C32: $180.00
A34: COSTO TOTAL MENSUAL | C34: $1,565.46
A35: COSTO TOTAL 3 MESES | C35: $4,696.38
A36: COSTO TOTAL 6 MESES | C36: $9,392.76
A37: COSTO TOTAL 12 MESES | C37: $18,785.52

Sheet RESUMEN
A1: Proyecto | B1: Sistema de gestion de citas: Fisioterapia y Rehabilitacion
A2: Propuesta | B2: 1
A3: Fecha | B3: 46037
A4: Duracion estimada (Meses) | B4: 4
A5: Integrantes | B5: Cordero Martin
B6: Tufiño Erick
B7: Ayuquina Danny
A9: Calculo por dia | B9: Horas
A10: Horas de trabajo por dia | B10: 2
A11: Horas de trabajo autonomo | B11: 1
A12: Total horas x dia | B12: =SUM(B10+B11) -> 3
A14: Calculo semanal
A15: Dias de trabajo a la semana | B15: 3
A16: Horas de trabajo semanal | B16: =B12*B15 -> 9
A18: Calculo semestral
A19: Total semanas de trabajo | B19: 16
A20: Total horas de trabajo x persona | B20: =B19*B16 -> 144
A21: Total horas de trabajo x equipo | B21: =B20*3 -> 432

Sheet Detalles - Ingenieros
A1: CÁLCULO DETALLADO - RECURSO HUMANO
A3: Información Base | B3: Valor | C3: Descripción
A4: Horas por semana | B4: 9 | C4: Horas que trabaja cada ingeniero
A5: Semanas por mes | B5: 4 | C5: Semanas estándar del mes
A6: Horas mensuales | B6: 36 | C6: 9 horas/semana × 4 semanas
A8: SCRUM Master | E8: Ingenieros Desarrolladores
A9: Ingeniero Software | B9: Cálculo | C9: Resultado | E9: Ingeniero Software | F9: Cálculo | G9: Resultado
A10: Salario mensual estimado | B10: $2,500.00 | C10: Estimación promedio Ecuador | E10: Salario mensual estimado | F10: $2,000.00 | G10: Estimación promedio Ecuador
A11: Costo por hora | B11: $2,500 / 160 | C11: $15.63 | E11: Costo por hora | F11: $2,000 / 160 | G11: $12.50
A12: Horas al mes (9 hr/semana) | B12: 9 × 4 | C12: 36 horas | E12: Horas al mes (9 hr/semana) | F12: 9 × 4 | G12: 36 horas
A13: Costo mensual por ingeniero | B13: $15,63 × 36 | C13: $562.68 | E13: Costo mensual por ingeniero | F13: $12.50 × 36 | G13: $450.00
A14: Total SCRUM MASTER | C14: 562.68 | E14: Total 2 ingenieros | F14: $450 × 2 | G14: 900
A16: TOTAL EQUIPO DE DESARROLLO: | B16: =SUM(C14+G14) -> 1462.68
A20: NOTA:El salario base de un ingeniero software es de $2,000 , mientras que un scrum master junior su salario es de $2,500 en Ecuador

Sheet Detalles - Equipos
A1: CÁLCULO DETALLADO - DEPRECIACIÓN DE EQUIPOS
A3: COMPUTADORAS
I4: Persona 1 | L4: Persona 2 | O4: Persona 3
A5: Equipo | B5: Modelo | C5: Valor Original | D5: Vida util (meses) | E5: Depreciación Mensual | F5: Meses de uso | G5: Subtotal | I5: Depreciación por persona | L5: Depreciación por persona | O5: Depreciación por persona
A6: PC 1 | B6: HP Pavilion-15-cc060wm | C6: 1000 | D6: 36 | E6: =C6/D6 -> 27.777778 | F6: 4 | G6: =F6*E6 -> 111.11111 | I6: Depreciación mensual | J6: =G6/4 -> 27.777778 | L6: Depreciación mensual | M6: =G7/4 -> 23.611111 | O6: Depreciación mensual | P6: =G8/4 -> 33.333333
A7: PC 2 | B7: Dell Inspiron 15 3511 | C7: 850 | D7: 36 | E7: =C7/D7 -> 23.611111 | F7: 4 | G7: =F7*E7 -> 94.444444 | I7: Depreciación semanal | J7: =J6/4 -> 6.9444444 | L7: Depreciación semanal | M7: =M6/4 -> 5.9027778 | O7: Depreciación semanal | P7: =P6/4 -> 8.3333333
A8: PC 3 | B8: LOQ 15ARP9-TYPE 83JC | C8: 1200 | D8: 36 | E8: =C8/D8 -> 33.333333 | F8: 4 | G8: =F8*E8 -> 133.33333 | I8: Depreciación diaria | J8: =J7/3 -> 2.3148148 | L8: Depreciación diaria | M8: =M7/3 -> 1.9675926 | O8: Depreciación diaria | P8: =P7/3 -> 2.7777778
A9: Total computadoras | G9: =SUM(G6:G8) -> 338.88889 | I9: Depreciación por hora | J9: =J8/3 -> 0.77160494 | L9: Depreciación por hora | M9: =M8/3 -> 0.6558642 | O9: Depreciación por hora | P9: =P8/3 -> 0.92592593
A12: CELULARES
A14: Equipo | B14: Modelo | C14: Valor Original | D14: Vida Útil (meses) | E14: Depreciación Mensual | F14: Meses de uso | G14: Subtotal | I14: Persona 1 | L14: Persona 2 | O14: Persona 3
A15: Celular 1 | B15: Xiami Redmi 15C | C15: 150 | D15: 36 | E15: =C15/D15 -> 4.1666667 | F15: 4 | G15: =E15*F15 -> 16.666667 | I15: Depreciación por persona | L15: Depreciación por persona | O15: Depreciación por persona
A16: Celular 2 | B16: Iphone SE | C16: 400 | D16: 36 | E16: =C16/D16 -> 11.111111 | F16: 4 | G16: =E16*F16 -> 44.444444 | I16: Depreciación mensual | J16: =G15/4 -> 4.1666667 | L16: Depreciación mensual | M16: =G16/4 -> 11.111111 | O16: Depreciación mensual | P16: =G17/4 -> 13.888889
A17: Celular 3 | B17: Samsung A54 5G | C17: 500 | D17: 36 | E17: =C17/D17 -> 13.888889 | F17: 4 | G17: =E17*F17 -> 55.555556 | I17: Depreciación semanal | J17: =J16/4 -> 1.0416667 | L17: Depreciación semanal | M17: =M16/4 -> 2.7777778 | O17: Depreciación semanal | P17: =P16/4 -> 3.4722222
A18: Total Celulares | G18: =SUM(G15:G17) -> 116.66667 | I18: Depreciación diaria | J18: =J17/3 -> 0.34722222 | L18: Depreciación diaria | M18: =M17/3 -> 0.92592593 | O18: Depreciación diaria | P18: =P17/3 -> 1.1574074
I19: Depreciación por hora | J19: =J18/3 -> 0.11574074 | L19: Depreciación por hora | M19: =M18/3 -> 0.30864198 | O19: Depreciación por hora | P19: =P18/3 -> 0.38580247
F21: Total depreciacion de equipos | G21: =G9+G18 -> 455.55556

Sheet Detalles - Servicios
A1: CÁLCULO DETALLADO - SERVICIOS E INFRAESTRUCTURA
N2: 50 horas*semana
A3: Rol | B3: N* Personas (CASA) | C3: Factura Internet | D3: Cuota Individual Internet | E3: Cuota por hora internet | F3: Cuota mensual internet | G3: Internet(4 Meses) | I3: Transporte x dia | J3: Factura transporte
A4: Scrum Master | B4: 4 | C4: 32.5 | D4: =(C4/B4) -> 8.125 | E4: =(D4/50) -> 0.1625 | F4: =(E4*20) -> 3.25 | G4: =(F4*4.5) -> 14.625 | I4: =(J4/20) -> 2 | J4: 40
A5: Ing.Req 1 | B5: 2 | C5: 16.37 | D5: =(C5/B5) -> 8.185 | E5: =(D5/50) -> 0.1637 | F5: =(E5*20) -> 3.274 | G5: =(F5*4.5) -> 14.733 | I5: =(J5/20) -> 1.5 | J5: 30
A6: Ing.Req 2 | B6: 4 | C6: 30 | D6: =(C6/B6) -> 7.5 | E6: =(D6/50) -> 0.15 | F6: =(E6*20) -> 3 | G6: =(F6*4.5) -> 13.5 | I6: =(J6/20) -> 2 | J6: 40
E7: =SUM(E4:E6) -> 0.4762 | F7: Total | G7: =SUM(G4:G6) -> 42.858 | I7: Total | J7: =SUM(J4:J6) -> 110
C10: Factura Luz | D10: Cuota Individual luz | E10: Cuota por hora Luz | F10: Cuenta mensual Luz | G10: Luz(4 Meses)
C11: 25 | D11: =(C11/B4) -> 6.25 | E11: =(D11/50) -> 0.125 | F11: =(E11*20) -> 2.5 | G11: =(F11*4.5) -> 11.25
C12: 16.37 | D12: =(C12/B5) -> 8.185 | E12: =(D12/50) -> 0.1637 | F12: =(E12*20) -> 3.274 | G12: =(F12*4.5) -> 14.733
C13: 25 | D13: =(C13/B6) -> 6.25 | E13: =(D13/50) -> 0.125 | F13: =(E13*20) -> 2.5 | G13: =(F13*4.5) -> 11.25
E14: =SUM(E11:E13) -> 0.4137 | F14: Total | G14: =SUM(G11:G13) -> 37.233
C16: Factura agua | D16: Costo individual agua | E16: Cuota por hora agua | F16: Costo mensual agua | G16: Agua(4,5 Meses)
C17: 20 | D17: =(C17/B4) -> 5 | E17: =(D17/50) -> 0.1 | F17: =(E17*20) -> 2 | G17: =(F17*4.5) -> 9
C18: 16.37 | D18: =(C18/B5) -> 8.185 | E18: =(D18/50) -> 0.1637 | F18: =(E18*20) -> 3.274 | G18: =(F18*4.5) -> 14.733
C19: 15 | D19: =(C19/B6) -> 3.75 | E19: =(D19/50) -> 0.075 | F19: =(E19*20) -> 1.5 | G19: =(F19*4.5) -> 6.75
E20: =SUM(E17:E19) -> 0.3387 | F20: Total | G20: =SUM(G17:G19) -> 30.483
F22: Total Servicios x Equipo de trabajo | G22: =SUM(J7+G7+G14+G20) -> 220.574
F24: Concepto por persona x hora | G24: =SUM(E7+E14+E20) -> 1.2286

Sheet Proyección
A1: PROYECCIÓN DE COSTOS - DIFERENTES PERÍODOS
A3: Período | B3: Costo Total (USD)
A4: Costo Mensual | B4: $1,565.46
A5: Costo 1 Mes | B5: $1,565.46
A6: Costo 3 Meses | B6: $4,696.38
A7: Costo 6 Meses | B7: $9,392.76
A8: Costo 12 Meses (1 Año) | B8: $18,785.52
A9: Costo 18 Meses | B9: $28,177.28
A10: Costo 24 Meses (2 Años) | B10: $37,569.04
A12: RESUMEN DE GASTOS | B12: Porcentaje del Total
A13: Recurso Humano | B13: 86.25%
A14: Depreciación Equipos | B14: 2.25%
A15: Servicios e Infraestructura | B15: 11.50%

Sheet Estimado propuesta 2
A1: Fase 1: Elicitacion
A2: Actividades | B2: Responsable | C2: Horas | D2: Rol | E2: Costo RH | F2: Costo material | G2: Gastos operativos | H2: Subtotal | J2: Gasto operativo por hora | K2: ='Detalles - Servicios'!G24 -> 1.2286
A3: Banco de preguntas | B3: G4 | C3: 3 | D3: Ing. De requisitos | E3: =C3*SUM(L13,L17,L21) -> 180 | F3: =3*C3*SUM(M4:M6) -> 28.472222 | G3: =3*C3*K2 -> 11.0574 | H3: =SUM(E3:G3) -> 219.52962 | M3: Total x persona
A4: Planificacion entrevista | B4: G4 | C4: 2 | D4: Ing. De requisitos | E4: =C4*SUM(L13,L17,L21) -> 120 | F4: =3*C4*SUM(M4:M6) -> 18.981481 | G4: =3*C4*K2 -> 7.3716 | H4: =SUM(E4:G4) -> 146.35308 | J4: Costo Material x hora - persona 1 | K4: ='Detalles - Equipos'!J9 -> 0.77160494 | L4: ='Detalles - Equipos'!J19 -> 0.11574074 | M4: =K4+L4 -> 0.88734568
A5: Ejecucion entrevista | B5: Danny Ayuquina | C5: 1.5 | D5: Ing. De requisitos | E5: =C5*L21 -> 30 | F5: =3*C5*M5 -> 4.3402778 | G5: =3*C5*K2 -> 5.5287 | H5: =SUM(E5:G5) -> 39.868978 | J5: Costo Material x hora - persona 2 | K5: ='Detalles - Equipos'!M9 -> 0.6558642 | L5: ='Detalles - Equipos'!M19 -> 0.30864198 | M5: =K5+L5 -> 0.96450617
A6: Minuta entrevista | B6: G4 | C6: 2 | D6: Ing. De requisitos | E6: =C6*SUM(L13,L13,L21) -> 120 | F6: =3*C6*SUM(M4:M6) -> 18.981481 | G6: =3*C6*K2 -> 7.3716 | H6: =SUM(E6:G6) -> 146.35308 | J6: Costo Material x hora - persona 3 | K6: ='Detalles - Equipos'!P9 -> 0.92592593 | L6: ='Detalles - Equipos'!P19 -> 0.38580247 | M6: =K6+L6 -> 1.3117284
A7: Defensa entrevista | B7: G4 | C7: 2 | D7: Ing. Req/ SM/ PO | E7: =C7*SUM(L11:L13) -> 150 | F7: =3*C7*SUM(M4:M6) -> 18.981481 | G7: =3*C7*K2 -> 7.3716 | H7: =SUM(E7:G7) -> 176.35308
A8: Planificacion brainstorming | B8: G4 | C8: 2 | D8: Ing. De requisitos | E8: =C8*SUM(L17,L20,L24) -> 40 | F8: =3*C8*SUM(M4:M6) -> 18.981481 | G8: =3*C8*K2 -> 7.3716 | H8: =SUM(E8:G8) -> 66.353081
A9: Ejecucion brainstorming | B9: Martin Cordero | C9: 1.5 | D9: Ing. De requisitos | E9: =C9*L13 -> 30 | F9: =3*C9*M6 -> 5.9027778 | G9: =3*C9*K2 -> 5.5287 | H9: =SUM(E9:G9) -> 41.431478
A10: Acta de reunion brainstorming | B10: Erick Tufiño | C10: 2 | D10: Ing. De requisitos | E10: =C9*L21 -> 30 | F10: =3*C10*M4 -> 5.3240741 | G10: =3*C10*K2 -> 7.3716 | H10: =SUM(E10:G10) -> 42.695674 | J10: Integrante | K10: Rol | L10: Costo*hora
A11: Defensa brainstorming | B11: G4 | C11: 2 | D11: Ing. Req/ SM/ PO | E11: =C11*L21 -> 40 | F11: =3*C11*SUM(M4:M6) -> 18.981481 | G11: =3*C11*K2 -> 7.3716 | H11: =SUM(E11:G11) -> 66.353081 | J11: Martin Cordero | K11: Scrum Master | L11: 30
A12: Subtotal Fase 1 | H12: =SUM(H3:H11) -> 945.29116 | K12: Product Owner | L12: 25
K13: Ingeniero de requisitos | L13: 20
K14: Diseñador UI/UX | L14: 25
A15: Fase 2: Analisis
A16: Actividades | B16: Responsable | C16: Horas | D16: Rol | E16: Costo RH | F16: Costo material | G16: Gastos operativos | H16: Subtotal | J16: Integrante | K16: Rol | L16: Costo*hora
A17: Diagrama CU situacion actual | B17: G4 | C17: 4 | D17: Ing. De requisitos | E17: =C17*SUM(L13,L17,L21) -> 240 | F17: =3*C17*SUM(M4:M6) -> 37.962963 | G17: =3*C17*K2 -> 14.7432 | H17: =SUM(E17:G17) -> 292.70616 | J17: Erick Tufiño | K17: Ingeniero de requisitos | L17: 20
A18: Defensa CU situacion actual y arbol de problemas | B18: G4 | C18: 2 | D18: Ing. Req/ SM/ PO | E18: =C18*SUM(L11:L13) -> 150 | F18: =3*C18*SUM(M4:M6) -> 18.981481 | G18: =3*C18*K2 -> 7.3716 | H18: =SUM(E18:G18) -> 176.35308 | K18: Diseñador UI/UX | L18: 25
A19: Diagrama CU propuesta solucion 2 | B19: Danny Ayuquina | C19: 6 | D19: Ing. De requisitos | E19: =C19*L21 -> 120 | F19: =3*C19*M4 -> 15.972222 | G19: =3*C19*K2 -> 22.1148 | H19: =SUM(E19:G19) -> 158.08702
A20: Arbol de problemas | B20: Martin Cordero | C20: 4 | D20: Ing. De requisitos | E20: =C20*L21 -> 80 | F20: =3*C20*M6 -> 15.740741 | G20: =3*C20*K2 -> 14.7432 | H20: =SUM(E20:G20) -> 110.48394 | J20: Integrante | K20: Rol | L20: Costo*hora
A21: Subtotal Fase 2 | H21: =SUM(H17:H20) -> 737.63021 | J21: Danny Ayuquina | K21: Ingeniero de requisitos | L21: 20
K22: Diseñador UI/UX | L22: 25
A24: Fase 3: Analisis
A25: Actividades | B25: Responsable | C25: Horas | D25: Rol | E25: Costo RH | F25: Costo material | G25: Gastos operativos | H25: Subtotal
A26: Descripcion CU Propuesta Sol. 2 | B26: Danny Ayuquina | C26: 5 | D26: Ing. De requisitos | E26: =C26*L21 -> 100 | F26: =3*C26*M4 -> 13.310185 | G26: =3*C26*K2 -> 18.429 | H26: =SUM(E26:G26) -> 131.73919
A27: Modelo Conceptual Proyecto | B27: Danny Ayuquina | C27: 4 | D27: Ing. De requisitos | E27: =C27*L21 -> 80 | F27: =3*C27*M5 -> 11.574074 | G27: =3*C27*K2 -> 14.7432 | H27: =SUM(E27:G27) -> 106.31727
A28: Redaccion RNF | B28: Erick Tufiño | C28: 4 | D28: Ing. De requisitos | E28: =C28*L21 -> 80 | F28: =3*C28*M4 -> 10.648148 | G28: =3*C28*K2 -> 14.7432 | H28: =SUM(E28:G28) -> 105.39135
A29: Redaccion documento SRS | B29: G4 | C29: 6 | D29: Ing. De requisitos | E29: =C29*SUM(L11:L13) -> 450 | F29: =3*C29*SUM(M4:M6) -> 56.944444 | G29: =3*C29*K2 -> 22.1148 | H29: =SUM(E29:G29) -> 529.05924
A30: Subtotal Fase 3 | H30: =SUM(H26:H29) -> 872.50705
A32: Fase 4: Verificar y ajustar
A33: Actividades | B33: Responsable | C33: Horas | D33: Rol | E33: Costo RH | F33: Costo material | G33: Gastos operativos | H33: Subtotal
A34: Envio documentacion al G3 | B34: Martin Cordero | C34: 1 | D34: Scrum Master | E34: =C34*L11 -> 30 | F34: =3*C34*M6 -> 3.9351852 | G34: =3*C34*K2 -> 3.6858 | H34: =SUM(E34:G34) -> 37.620985
A35: Diseño de interfaces G3 | B35: G4 | C35: 6 | D35: UI/UX | E35: =C35*SUM(L14,L18,L22) -> 450 | F35: =3*C35*SUM(M4:M6) -> 56.944444 | G35: =3*C35*K2 -> 22.1148 | H35: =SUM(E35:G35) -> 529.05924
A36: Defensa interfaces | B36: G4 | C36: 2 | D36: UI/UX | E36: =C36*SUM(L14,L18,L22) -> 150 | F36: =3*C36*SUM(M4:M6) -> 18.981481 | G36: =3*C36*K2 -> 7.3716 | H36: =SUM(E36:G36) -> 176.35308
A37: Defensa documento SRS | B37: G4 | C37: 2 | D37: Ing. Req/ SM/ PO | E37: =C37*SUM(L11:L13) -> 150 | F37: =3*C37*SUM(M4:M6) -> 18.981481 | G37: =3*C37*K2 -> 7.3716 | H37: =SUM(E37:G37) -> 176.35308
A38: Subtotal Fase 4 | H38: =SUM(H34:H37) -> 919.38639
A41: Fase 5: Administrar
A42: Actividades | B42: Responsable | C42: Horas | D42: Rol | E42: Costo RH | F42: Costo material | G42: Gastos operativos | H42: Subtotal
A43: Planificacion general del proyecto | B43: Martin Cordero | C43: 6 | D43: Scrum Master/ Product Owner | E43: =C43*SUM(L11+L12) -> 330 | F43: =3*C43*M6 -> 23.611111 | G43: =3*C43*K2 -> 22.1148 | H43: =SUM(E43:G43) -> 375.72591
A44: Gestion y seguimiento en Project | B44: Martin Cordero | C44: 12 | D44: Scrum Master/ Product Owner | E44: =C44*SUM(L11+L12) -> 660 | F44: =3*C44*M6 -> 47.222222 | G44: =3*C44*K2 -> 44.2296 | H44: =SUM(E44:G44) -> 751.45182
...
